<?xml version="1.0"?>
<robot name="dual_open_manipulator_p">

  <!-- Base Link -->
  <link name="world"/>

  <link name="base_plate">
    <visual>
      <geometry>
        <box size="0.5 1.0 0.02"/>
      </geometry>
      <material name="grey">
        <color rgba="0.5 0.5 0.5 1.0"/>
      </material>
    </visual>
    <collision>
      <geometry>
        <box size="0.5 1.0 0.02"/>
      </geometry>
    </collision>
  </link>

  <joint name="world_to_base" type="fixed">
    <parent link="world"/>
    <child link="base_plate"/>
    <origin xyz="0 0 0" rpy="0 0 0"/>
  </joint>

  <!-- Left Arm -->
  <link name="left_base_link">
    <visual>
      <geometry><mesh filename="package://open_manipulator_p_description/meshes/link1.stl" scale="0.001 0.001 0.001"/></geometry>
      <material name="black"><color rgba="0.1 0.1 0.1 1.0"/></material>
    </visual>
  </link>
  <joint name="left_base_joint" type="fixed">
    <parent link="base_plate"/>
    <child link="left_base_link"/>
    <origin xyz="0 0.25 0.01" rpy="0 0 0"/>
  </joint>

  <link name="left_link1"/>
  <joint name="left_joint1" type="revolute">
    <parent link="left_base_link"/>
    <child link="left_link1"/>
    <origin xyz="0 0 0.126" rpy="0 0 0"/>
    <axis xyz="0 0 1"/>
    <limit lower="-3.14159" upper="3.14159" effort="100" velocity="1.0"/>
  </joint>

  <link name="left_link2"/>
  <joint name="left_joint2" type="revolute">
    <parent link="left_link1"/>
    <child link="left_link2"/>
    <origin xyz="0 0 0.033" rpy="0 0 0"/>
    <axis xyz="0 1 0"/>
    <limit lower="-1.5708" upper="1.5708" effort="100" velocity="1.0"/>
  </joint>

  <link name="left_link3"/>
  <joint name="left_joint3" type="revolute">
    <parent link="left_link2"/>
    <child link="left_link3"/>
    <origin xyz="0 0 0.264" rpy="0 0 0"/>
    <axis xyz="0 1 0"/>
    <limit lower="-1.5708" upper="2.3562" effort="100" velocity="1.0"/>
  </joint>

  <link name="left_link4"/>
  <joint name="left_joint4" type="revolute">
    <parent link="left_link3"/>
    <child link="left_link4"/>
    <origin xyz="0 0 0.052" rpy="0 0 0"/>
    <axis xyz="0 0 1"/>
    <limit lower="-3.14159" upper="3.14159" effort="100" velocity="1.0"/>
  </joint>

  <link name="left_link5"/>
  <joint name="left_joint5" type="revolute">
    <parent link="left_link4"/>
    <child link="left_link5"/>
    <origin xyz="0 0 0.211" rpy="0 0 0"/>
    <axis xyz="0 1 0"/>
    <limit lower="-1.5708" upper="1.5708" effort="100" velocity="1.0"/>
  </joint>

  <link name="left_link6"/>
  <joint name="left_joint6" type="revolute">
    <parent link="left_link5"/>
    <child link="left_link6"/>
    <origin xyz="0 0 0.052" rpy="0 0 0"/>
    <axis xyz="0 0 1"/>
    <limit lower="-3.14159" upper="3.14159" effort="100" velocity="1.0"/>
  </joint>

  <!-- Right Arm -->
  <link name="right_base_link">
    <visual>
      <geometry><mesh filename="package://open_manipulator_p_description/meshes/link1.stl" scale="0.001 0.001 0.001"/></geometry>
      <material name="black"><color rgba="0.1 0.1 0.1 1.0"/></material>
    </visual>
  </link>
  <joint name="right_base_joint" type="fixed">
    <parent link="base_plate"/>
    <child link="right_base_link"/>
    <origin xyz="0 -0.25 0.01" rpy="0 0 0"/>
  </joint>

  <link name="right_link1"/>
  <joint name="right_joint1" type="revolute">
    <parent link="right_base_link"/>
    <child link="right_link1"/>
    <origin xyz="0 0 0.126" rpy="0 0 0"/>
    <axis xyz="0 0 1"/>
    <limit lower="-3.14159" upper="3.14159" effort="100" velocity="1.0"/>
  </joint>

  <link name="right_link2"/>
  <joint name="right_joint2" type="revolute">
    <parent link="right_link1"/>
    <child link="right_link2"/>
    <origin xyz="0 0 0.033" rpy="0 0 0"/>
    <axis xyz="0 1 0"/>
    <limit lower="-1.5708" upper="1.5708" effort="100" velocity="1.0"/>
  </joint>

  <link name="right_link3"/>
  <joint name="right_joint3" type="revolute">
    <parent link="right_link2"/>
    <child link="right_link3"/>
    <origin xyz="0 0 0.264" rpy="0 0 0"/>
    <axis xyz="0 1 0"/>
    <limit lower="-1.5708" upper="2.3562" effort="100" velocity="1.0"/>
  </joint>

  <link name="right_link4"/>
  <joint name="right_joint4" type="revolute">
    <parent link="right_link3"/>
    <child link="right_link4"/>
    <origin xyz="0 0 0.052" rpy="0 0 0"/>
    <axis xyz="0 0 1"/>
    <limit lower="-3.14159" upper="3.14159" effort="100" velocity="1.0"/>
  </joint>

  <link name="right_link5"/>
  <joint name="right_joint5" type="revolute">
    <parent link="right_link4"/>
    <child link="right_link5"/>
    <origin xyz="0 0 0.211" rpy="0 0 0"/>
    <axis xyz="0 1 0"/>
    <limit lower="-1.5708" upper="1.5708" effort="100" velocity="1.0"/>
  </joint>

  <link name="right_link6"/>
  <joint name="right_joint6" type="revolute">
    <parent link="right_link5"/>
    <child link="right_link6"/>
    <origin xyz="0 0 0.052" rpy="0 0 0"/>
    <axis xyz="0 0 1"/>
    <limit lower="-3.14159" upper="3.14159" effort="100" velocity="1.0"/>
  </joint>

</robot>
